Workbook

Sheet OCTOBER
B1: Total Hari | C1: 31 | G1: Copy for Closing Sales ( hanya yang di dalam kotak)
B2: Tanggal | C2: 13 | D2: ( isi dengan tanggal pengisian terakhir) | G2: 46308
G3: Total Daily Sales: | H3: =N21 -> 158920000
G4: Total MTD: | H4: =+N40 -> 4301335870 | I4: =O40 -> 0.32658865
G5: Ekspol: | H5: =N41 -> 10257031690 | I5: =N42 -> 0.77878833
G6: TL: | H6: =O40 -> 0.32658865 | I6: =100%/$C$1*C2 -> 0.41935484
B7: Sales tolong di isi oleh masing2 toko
A8: Date | B8: PI | C8: PP | D8: PS | E8: SC | F8: TP | G8: VK | H8: PIM | I8: KOKAS | J8: Icon Bali | K8: PASKAL | L8: TBOS | N8: Total TB | O8: Achievement
A9: 46296 | B9: 72440000 | D9: 90555000 | E9: 35260000 | F9: 16605000 | G9: 0 | H9: 26039620 | I9: 8200000 | J9: 5000000 | K9: 0 | L9: 0 | N9: =SUM(B9:M9) -> 254099620
A10: 46297 | B10: 51700000 | D10: 49750000 | E10: 30620000 | F10: 54060000 | G10: 5440000 | H10: 46500000 | I10: 0 | J10: 57670000 | K10: 0 | L10: 0 | N10: =SUM(B10:M10) -> 295740000
A11: 46298 | B11: 64600000 | D11: 72630000 | E11: 58870000 | F11: 49790000 | G11: 11730000 | H11: 85920000 | I11: 23300000 | J11: 14700000 | K11: 0 | L11: 0 | N11: =SUM(B11:M11) -> 381540000
A12: 46299 | B12: 164000000 | D12: 194250000 | E12: 98490000 | F12: 42960000 | G12: 44183750 | H12: 103740000 | I12: 48170000 | J12: 70265000 | K12: 0 | L12: 0 | N12: =SUM(B12:M12) -> 766058750
A13: 46300 | B13: 34100000 | D13: 82690000 | E13: 48990000 | F13: 14850000 | G13: 9785000 | H13: 10200000 | I13: 0 | J13: 27388000 | K13: 0 | L13: 0 | N13: =SUM(B13:M13) -> 228003000
A14: 46301 | B14: 51900000 | D14: 70540000 | E14: 13400000 | F14: 84880000 | G14: 8540000 | H14: 38600000 | I14: 16500000 | J14: 612000 | K14: 0 | L14: 5600000 | N14: =SUM(B14:M14) -> 290572000
A15: 46302 | B15: 24200000 | D15: 13865000 | E15: 62530000 | F15: 23200000 | G15: 25671250 | H15: 6500000 | I15: 34750000 | J15: 30400000 | K15: 0 | L15: 0 | N15: =SUM(B15:M15) -> 221116250
A16: 46303 | B16: 26200000 | D16: 29950000 | E16: 72405000 | F16: 47520000 | G16: 19250000 | H16: 29050000 | I16: 22670000 | J16: 35700000 | K16: 0 | L16: 31615000 | N16: =SUM(B16:M16) -> 314360000
A17: 46304 | B17: 56510000 | D17: 31150000 | E17: 32850000 | F17: 52110000 | G17: 21310000 | H17: 40955000 | I17: 13500000 | J17: 18900000 | K17: 0 | L17: 22655000 | N17: =SUM(B17:L17) -> 289940000
A18: 46305 | B18: 134510000 | D18: 18900000 | E18: 101480000 | F18: 48990000 | G18: 19141250 | H18: 58490000 | I18: 5800000 | J18: 0 | K18: 0 | L18: 0 | N18: =SUM(B18:L18) -> 387311250
A19: 46306 | B19: 67910000 | D19: 65600000 | E19: 53000000 | F19: 42750000 | G19: 32972500 | H19: 60025000 | I19: 60595000 | J19: 5280000 | L19: 0 | N19: =SUM(B19:L19) -> 388132500
A20: 46307 | B20: 53750000 | D20: 16680000 | E20: 116990000 | F20: 65970000 | G20: 2975000 | H20: 24500000 | I20: 7900000 | J20: 18800000 | L20: 17977500 | N20: =SUM(B20:L20) -> 325542500
A21: 46308 | B21: 29040000 | D21: 10980000 | E21: 46870000 | F21: 37610000 | G21: 3800000 | H21: - | I21: 15900000 | J21: 14720000 | L21: 0 | N21: =SUM(B21:L21) -> 158920000
A22: 46309 | N22: =SUM(B22:L22) -> 0
A23: 46310 | N23: =SUM(B23:L23) -> 0
A24: 46311 | N24: =SUM(B24:L24) -> 0
A25: 46312 | N25: =SUM(B25:L25) -> 0
A26: 46313 | N26: =SUM(B26:L26) -> 0
A27: 46314 | N27: =SUM(B27:L27) -> 0
A28: 46315 | N28: =SUM(B28:L28) -> 0
A29: 46316 | N29: =SUM(B29:L29) -> 0
A30: 46317 | N30: =SUM(B30:L30) -> 0
A31: 46318 | N31: =SUM(B31:L31) -> 0
A32: 46319 | N32: =SUM(B32:L32) -> 0
A33: 46320 | N33: =SUM(B33:L33) -> 0
... A37: 46324 | N37: =SUM(B37:L37) -> 0
A38: 46325
A39: 46326 | N39: =SUM(B39:L39) -> 0
A40: Total Month | B40: =SUM(B9:B39) -> 830860000 | C40: =SUM(C9:C39) -> 0 | D40: =SUM(D9:D39) -> 747540000 | E40: =SUM(E9:E39) -> 771755000 | F40: =SUM(F9:F39) -> 581295000 | G40: =SUM(G9:G39) -> 204798750 | H40: =SUM(H9:H39) -> 530519620 | I40: =SUM(I9:I39) -> 257285000 | ... L40: =SUM(L9:L39) -> 77847500 | N40: =SUM(N9:N39) -> 4301335870 | O40: =N40/N43 -> 0.32658865
A41: Expol | B41: =B40*$C$1/$C$2 -> 1981281538 | C41: =C40*$C$1/$C$2 -> 0 | D41: =D40*$C$1/$C$2 -> 1782595385 | E41: =E40*$C$1/$C$2 -> 1840338846 | F41: =F40*$C$1/$C$2 -> 1386165000 | G41: =G40/C2*C1 -> 488366250 | H41: =H40*$C$1/$C$2 -> 1265085248 | I41: =I40*$C$1/$C$2 -> 6.1352577e+08 | J41: =J40*$C$1/$C$2 -> 7.1403731e+08 | K41: =K40*$C$1/$C$2 -> 0 | L41: =L40*$C$1/$C$2 -> 1.8563635e+08 | M41: =M40*$C$1/$C$2 -> 0 | N41: =SUM(B41:M41) -> 10257031690
A42: % Expol | B42: =B41/B43 -> 1.0031805 | C42: =C41/C43 -> 0 | D42: =D41/D43 -> 0.79226462 | E42: =E41/E43 -> 0.73613554 | F42: =F41/F43 -> 0.74927838 | G42: =G41/G43 -> 0.94828398 | H42: =H41/H43 -> 0.920062 | I42: =I41/I43 -> 0.54535624 | ... L42: =L41/L43 -> 0.56168335 | N42: =N41/N43 -> 0.77878833
A43: Target | B43: 1975000000 | C43: 230000000 | D43: 2250000000 | E43: 2500000000 | F43: 1850000000 | G43: 515000000 | H43: 1375000000 | I43: 1125000000 | J43: 850000000 | K43: 170000000 | L43: 330500000 | N43: =SUM(B43:M43) -> 13170500000
...

Sheet October Detail
A1: Date | B1: PI | G1: PP | L1: PS | Q1: SC | V1: TP | AA1: VK | AF1: PIM | AK1: KOKAS | AP1: Icon Bali | AU1: Total
B2: Walk In | C2: CT | D2: Appointments | E2: Total Store | F2: Social Media | G2: Walk In | H2: CT | I2: Appointments | J2: Total Store | K2: Social Media | L2: Walk In | M2: CT | N2: Appointments | O2: Total Store | P2: Social Media | Q2: Walk In | R2: CT | S2: Appointments | T2: Total Store | U2: Social Media | V2: Walk In | W2: CT | X2: Appointments | Y2: Total Store | Z2: Social Media | AA2: Walk In | AB2: CT | AC2: Appointments | AD2: Total Store | AE2: Social Media | AF2: Walk In | AG2: CT | AH2: Appointments | AI2: Total Store | AJ2: Social Media | AK2: Walk In | AL2: CT | AM2: Appointments | AN2: Total Store | AO2: Social Media | AP2: Walk In | AQ2: CT | AR2: Appointments | AS2: Total Store | AT2: Social Media | AU2: Walk In | AV2: CT | AW2: Appointments | AX2: Total Store | AY2: Social Media
A3: 46296 | B3: =OCTOBER!B9-C3-D3 -> 45840000 | D3: 26600000 | E3: =sum(B3:D3) -> 72440000 | J3: =sum(G3:I3) -> 0 | L3: 61240000 | M3: - | N3: 29315000 | O3: =sum(L3:N3) -> 90555000 | P3: - | Q3: =OCTOBER!E9-R3-S3 -> 25500000 | S3: 9760000 | T3: =sum(Q3:S3) -> 35260000 | X3: 16605000 | Y3: =sum(V3:X3) -> 16605000 | AA3: 0 | AB3: 0 | AC3: 0 | AD3: =sum(AA3:AC3) -> 0 | AF3: =+OCTOBER!H9-AG3-AH3 -> 26039620 | AG3: 0 | AH3: 0 | AI3: =sum(AF3:AH3) -> 26039620 | AJ3: 0 | AK3: =OCTOBER!I9-(AL3+AM3+AO3) -> 0 | AM3: 8200000 | AN3: =sum(AK3:AM3) -> 8200000 | AQ3: 5000000 | AS3: =sum(AP3:AR3) -> 5000000 | AU3: =SUM(B3,G3,L3,Q3,V3,AA3,AF3,AK3,AP3) -> 158619620 | AV3: =SUM(C3,H3,M3,R3,W3,AB3,AG3,AL3,AQ3) -> 5000000 | AW3: =SUM(D3,I3,N3,S3,X3,AC3,AH3,AM3,AR3) -> 90480000 | AX3: =E3+J3+O3+T3+Y3+AD3+AI3+AN3+AS3 -> 254099620
A4: 46297 | B4: =OCTOBER!B10-C4-D4 -> 26200000 | D4: 25500000 | E4: =sum(B4:D4) -> 51700000 | J4: =sum(G4:I4) -> 0 | L4: 37550000 | M4: 12200000 | N4: - | O4: =sum(L4:N4) -> 49750000 | P4: - | Q4: =OCTOBER!E10-R4-S4 -> 24320000 | S4: 6300000 | T4: =sum(Q4:S4) -> 30620000 | V4: 37620000 | X4: 16440000 | Y4: =sum(V4:X4) -> 54060000 | AA4: 2592500 | AB4: 2847500 | AD4: =sum(AA4:AC4) -> 5440000 | AE4: 2847500 | AF4: =+OCTOBER!H10-AG4-AH4 -> 30000000 | AG4: 0 | AH4: 16500000 | AI4: =sum(AF4:AH4) -> 46500000 | AJ4: 0 | AK4: =OCTOBER!I10-(AL4+AM4+AO4) -> 0 | AN4: =sum(AK4:AM4) -> 0 | AP4: 45070000 | AR4: 12600000 | AS4: =sum(AP4:AR4) -> 57670000 | AU4: =SUM(B4,G4,L4,Q4,V4,AA4,AF4,AK4,AP4) -> 203352500 | AV4: =SUM(C4,H4,M4,R4,W4,AB4,AG4,AL4,AQ4) -> 15047500 | AW4: =SUM(D4,I4,N4,S4,X4,AC4,AH4,AM4,AR4) -> 77340000 | AX4: =E4+J4+O4+T4+Y4+AD4+AI4+AN4+AS4 -> 295740000
A5: 46298 | B5: =OCTOBER!B11-C5-D5 -> 38990000 | D5: 25610000 | E5: =sum(B5:D5) -> 64600000 | J5: =sum(G5:I5) -> 0 | L5: 38210000 | M5: - | N5: 34420000 | O5: =sum(L5:N5) -> 72630000 | P5: - | Q5: =OCTOBER!E11-R5-S5 -> 26010000 | S5: 32860000 | T5: =sum(Q5:S5) -> 58870000 | V5: =6000000+5740000 -> 11740000 | X5: =12750000+8300000+17000000 -> 38050000 | Y5: =sum(V5:X5) -> 49790000 | AA5: 11730000 | AD5: =sum(AA5:AC5) -> 11730000 | AF5: =+OCTOBER!H11-AG5-AH5 -> 69420000 | AG5: 0 | AH5: 16500000 | AI5: =sum(AF5:AH5) -> 85920000 | AJ5: 0 | AK5: =OCTOBER!I11-(AL5+AM5+AO5) -> 23300000 | AN5: =sum(AK5:AM5) -> 23300000 | AR5: 14700000 | AS5: =sum(AP5:AR5) -> 14700000 | AU5: =SUM(B5,G5,L5,Q5,V5,AA5,AF5,AK5,AP5) -> 219400000 | AV5: =SUM(C5,H5,M5,R5,W5,AB5,AG5,AL5,AQ5) -> 0 | AW5: =SUM(D5,I5,N5,S5,X5,AC5,AH5,AM5,AR5) -> 162140000 | AX5: =E5+J5+O5+T5+Y5+AD5+AI5+AN5+AS5 -> 381540000
A6: 46299 | B6: =OCTOBER!B12-C6-D6 -> 109300000 | D6: 54700000 | E6: =sum(B6:D6) -> 164000000 | J6: =sum(G6:I6) -> 0 | L6: 66830000 | M6: 11200000 | N6: 116220000 | O6: =sum(L6:N6) -> 194250000 | P6: - | Q6: =OCTOBER!E12-R6-S6 -> 51700000 | S6: 46790000 | T6: =sum(Q6:S6) -> 98490000 | V6: 7600000 | W6: 27760000 | X6: 7600000 | Y6: =sum(V6:X6) -> 42960000 | AA6: 44183750 | AD6: =sum(AA6:AC6) -> 44183750 | AF6: =+OCTOBER!H12-AG6-AH6 -> 54550000 | AG6: 0 | AH6: =+32850000+5040000+11300000 -> 49190000 | AI6: =sum(AF6:AH6) -> 103740000 | AJ6: 0 | AK6: =OCTOBER!I12-(AL6+AM6+AO6) -> 18200000 | AM6: 29970000 | AN6: =sum(AK6:AM6) -> 48170000 | AP6: 70265000 | AQ6: 0 | AR6: 0 | AS6: =sum(AP6:AR6) -> 70265000 | AU6: =SUM(B6,G6,L6,Q6,V6,AA6,AF6,AK6,AP6) -> 422628750 | AV6: =SUM(C6,H6,M6,R6,W6,AB6,AG6,AL6,AQ6) -> 38960000 | AW6: =SUM(D6,I6,N6,S6,X6,AC6,AH6,AM6,AR6) -> 304470000 | AX6: =E6+J6+O6+T6+Y6+AD6+AI6+AN6+AS6 -> 766058750
A7: 46300 | B7: 34100000 | D7: - | E7: =sum(B7:D7) -> 34100000 | J7: =sum(G7:I7) -> 0 | L7: 58540000 | M7: - | N7: 24150000 | O7: =sum(L7:N7) -> 82690000 | P7: - | Q7: =OCTOBER!E13-R7-S7 -> 31600000 | S7: 17390000 | T7: =sum(Q7:S7) -> 48990000 | X7: 14850000 | Y7: =sum(V7:X7) -> 14850000 | AA7: 5880000 | AB7: 3905000 | AD7: =sum(AA7:AC7) -> 9785000 | AE7: 3905000 | AF7: =+OCTOBER!H13-AG7-AH7 -> 6400000 | AG7: 0 | AH7: 3800000 | AI7: =sum(AF7:AH7) -> 10200000 | AJ7: - | AK7: =OCTOBER!I13-(AL7+AM7+AO7) -> 0 | AN7: =sum(AK7:AM7) -> 0 | AP7: 27388000 | AS7: =sum(AP7:AR7) -> 27388000 | AU7: =SUM(B7,G7,L7,Q7,V7,AA7,AF7,AK7,AP7) -> 163908000 | AV7: =SUM(C7,H7,M7,R7,W7,AB7,AG7,AL7,AQ7) -> 3905000 | AW7: =SUM(D7,I7,N7,S7,X7,AC7,AH7,AM7,AR7) -> 60190000 | AX7: =E7+J7+O7+T7+Y7+AD7+AI7+AN7+AS7 -> 228003000
A8: 46301 | B8: =OCTOBER!B14-C8-D8 -> 27700000 | D8: 24200000 | E8: =sum(B8:D8) -> 51900000 | J8: =sum(G8:I8) -> 0 | L8: 37100000 | M8: - | N8: 33440000 | O8: =sum(L8:N8) -> 70540000 | P8: - | Q8: =OCTOBER!E14-R8-S8 -> 13400000 | T8: =sum(Q8:S8) -> 13400000 | V8: 59780000 | X8: 25100000 | Y8: =sum(V8:X8) -> 84880000 | AA8: 8540000 | AD8: =sum(AA8:AC8) -> 8540000 | AF8: =+OCTOBER!H14-AG8-AH8 -> 21800000 | AG8: 0 | AH8: 16800000 | AI8: =sum(AF8:AH8) -> 38600000 | AJ8: 0 | AK8: =OCTOBER!I14-(AL8+AM8+AO8) -> 0 | AM8: 16500000 | AN8: =sum(AK8:AM8) -> 16500000 | AO8: 0 | AP8: 612000 | AQ8: 0 | AR8: 0 | AS8: =sum(AP8:AR8) -> 612000 | AU8: =SUM(B8,G8,L8,Q8,V8,AA8,AF8,AK8,AP8) -> 168932000 | AV8: =SUM(C8,H8,M8,R8,W8,AB8,AG8,AL8,AQ8) -> 0 | AW8: =SUM(D8,I8,N8,S8,X8,AC8,AH8,AM8,AR8) -> 116040000 | AX8: =E8+J8+O8+T8+Y8+AD8+AI8+AN8+AS8 -> 284972000
A9: 46302 | B9: =OCTOBER!B15-C9-D9 -> 24200000 | E9: =sum(B9:D9) -> 24200000 | J9: =sum(G9:I9) -> 0 | L9: 1465000 | M9: - | N9: 12400000 | O9: =sum(L9:N9) -> 13865000 | P9: - | Q9: =OCTOBER!E15-R9-S9 -> 40930000 | S9: 21600000 | T9: =sum(Q9:S9) -> 62530000 | V9: 23200000 | Y9: =sum(V9:X9) -> 23200000 | AA9: 25671250 | AD9: =sum(AA9:AC9) -> 25671250 | AF9: =+OCTOBER!H15-AG9-AH9 -> 6500000 | AG9: 0 | AH9: 0 | AI9: =sum(AF9:AH9) -> 6500000 | AJ9: 0 | AK9: =OCTOBER!I15-(AL9+AM9+AO9) -> 25500000 | AM9: 9250000 | AN9: =sum(AK9:AM9) -> 34750000 | AP9: 30400000 | AS9: =sum(AP9:AR9) -> 30400000 | AU9: =SUM(B9,G9,L9,Q9,V9,AA9,AF9,AK9,AP9) -> 177866250 | AV9: =SUM(C9,H9,M9,R9,W9,AB9,AG9,AL9,AQ9) -> 0 | AW9: =SUM(D9,I9,N9,S9,X9,AC9,AH9,AM9,AR9) -> 43250000 | AX9: =E9+J9+O9+T9+Y9+AD9+AI9+AN9+AS9 -> 221116250
A10: 46303 | B10: =OCTOBER!B16-C10-D10 -> 10700000 | D10: 15500000 | E10: =sum(B10:D10) -> 26200000 | J10: =sum(G10:I10) -> 0 | L10: 10500000 | M10: 19450000 | N10: - | O10: =sum(L10:N10) -> 29950000 | P10: - | Q10: =OCTOBER!E16-R10-S10 -> 46405000 | R10: 9500000 | S10: 16500000 | T10: =sum(Q10:S10) -> 72405000 | V10: 15720000 | X10: 31800000 | Y10: =sum(V10:X10) -> 47520000 | AA10: 19250000 | AD10: =sum(AA10:AC10) -> 19250000 | AF10: =+OCTOBER!H16-AG10-AH10 -> 21300000 | AG10: 0 | AH10: 7750000 | AI10: =sum(AF10:AH10) -> 29050000 | AJ10: 0 | AK10: =OCTOBER!I16-(AL10+AM10+AO10) -> 16870000 | AM10: 5800000 | AN10: =sum(AK10:AM10) -> 22670000 | AP10: 15520000 | AR10: 20180000 | AS10: =sum(AP10:AR10) -> 35700000 | AU10: =SUM(B10,G10,L10,Q10,V10,AA10,AF10,AK10,AP10) -> 156265000 | AV10: =SUM(C10,H10,M10,R10,W10,AB10,AG10,AL10,AQ10) -> 28950000 | AW10: =SUM(D10,I10,N10,S10,X10,AC10,AH10,AM10,AR10) -> 97530000 | AX10: =E10+J10+O10+T10+Y10+AD10+AI10+AN10+AS10 -> 282745000
A11: 46304 | B11: =OCTOBER!B17-C11-D11 -> 24410000 | D11: 32100000 | E11: =sum(B11:D11) -> 56510000 | J11: =sum(G11:I11) -> 0 | L11: 21050000 | M11: 10100000 | N11: - | O11: =sum(L11:N11) -> 31150000 | P11: - | Q11: =OCTOBER!E17-R11-S11 -> 14650000 | S11: 18200000 | T11: =sum(Q11:S11) -> 32850000 | V11: 52110000 | Y11: =sum(V11:X11) -> 52110000 | AA11: 21310000 | AD11: =sum(AA11:AC11) -> 21310000 | AF11: =+OCTOBER!H17-AG11-AH11 -> 12955000 | AG11: 6400000 | AH11: 21600000 | AI11: =sum(AF11:AH11) -> 40955000 | AJ11: 0 | AM11: 13500000 | AN11: =sum(AK11:AM11) -> 13500000 | AP11: 18900000 | AS11: =sum(AP11:AR11) -> 18900000 | AU11: =SUM(B11,G11,L11,Q11,V11,AA11,AF11,AK11,AP11) -> 165385000 | AV11: =SUM(C11,H11,M11,R11,W11,AB11,AG11,AL11,AQ11) -> 16500000 | AW11: =SUM(D11,I11,N11,S11,X11,AC11,AH11,AM11,AR11) -> 85400000 | AX11: =E11+J11+O11+T11+Y11+AD11+AI11+AN11+AS11 -> 267285000
A12: 46305 | B12: =OCTOBER!B18-C12-D12 -> 56740000 | D12: 77770000 | E12: =sum(B12:D12) -> 134510000 | J12: =sum(G12:I12) -> 0 | L12: 5300000 | M12: - | N12: 13600000 | O12: =sum(L12:N12) -> 18900000 | P12: - | Q12: =OCTOBER!E18-R12-S12 -> 60130000 | S12: 41350000 | T12: =sum(Q12:S12) -> 101480000 | V12: 22050000 | X12: 26940000 | Y12: =sum(V12:X12) -> 48990000 | AA12: 19141250 | AD12: =sum(AA12:AC12) -> 19141250 | AF12: =+OCTOBER!H18-AG12-AH12 -> 25250000 | AG12: 7600000 | AH12: 25640000 | AI12: =sum(AF12:AH12) -> 58490000 | AJ12: 0 | AK12: =OCTOBER!I18-(AL12+AM12+AO12) -> 5800000 | AN12: =sum(AK12:AM12) -> 5800000 | AP12: 0 | AQ12: 0 | AR12: 0 | AS12: =sum(AP12:AR12) -> 0 | AU12: =SUM(B12,G12,L12,Q12,V12,AA12,AF12,AK12,AP12) -> 194411250 | AV12: =SUM(C12,H12,M12,R12,W12,AB12,AG12,AL12,AQ12) -> 7600000 | AW12: =SUM(D12,I12,N12,S12,X12,AC12,AH12,AM12,AR12) -> 185300000 | AX12: =E12+J12+O12+T12+Y12+AD12+AI12+AN12+AS12 -> 387311250
A13: 46306 | B13: =OCTOBER!B19-C13-D13 -> 30110000 | D13: 37800000 | E13: =sum(B13:D13) -> 67910000 | J13: =sum(G13:I13) -> 0 | L13: 40850000 | M13: - | N13: 24750000 | O13: =sum(L13:N13) -> 65600000 | P13: - | Q13: =OCTOBER!E19-R13-S13 -> 30700000 | S13: 22300000 | T13: =sum(Q13:S13) -> 53000000 | V13: 35350000 | X13: 7400000 | Y13: =sum(V13:X13) -> 42750000 | AA13: 12082500 | AB13: 17490000 | AC13: 3400000 | AD13: =sum(AA13:AC13) -> 32972500 | AF13: =+OCTOBER!H19-AG13-AH13 -> 26105000 | AG13: 0 | AH13: 33920000 | AI13: =sum(AF13:AH13) -> 60025000 | AJ13: 0 | AK13: =OCTOBER!I19-(AL13+AM13+AO13) -> 31975000 | AM13: =22600000+6020000 -> 28620000 | AN13: =sum(AK13:AM13) -> 60595000 | AP13: 5280000 | AS13: =sum(AP13:AR13) -> 5280000 | AU13: =SUM(B13,G13,L13,Q13,V13,AA13,AF13,AK13,AP13) -> 212452500 | AV13: =SUM(C13,H13,M13,R13,W13,AB13,AG13,AL13,AQ13) -> 17490000 | AW13: =SUM(D13,I13,N13,S13,X13,AC13,AH13,AM13,AR13) -> 158190000 | AX13: =E13+J13+O13+T13+Y13+AD13+AI13+AN13+AS13 -> 388132500
A14: 46307 | B14: =OCTOBER!B20-C14-D14 -> 23400000 | D14: 30350000 | E14: =sum(B14:D14) -> 53750000 | J14: =sum(G14:I14) -> 0 | L14: 9400000 | M14: - | N14: 7280000 | O14: =sum(L14:N14) -> 16680000 | P14: - | Q14: =OCTOBER!E20-R14-S14 -> 66890000 | S14: 50100000 | T14: =sum(Q14:S14) -> 116990000 | V14: 30200000 | X14: 35770000 | Y14: =sum(V14:X14) -> 65970000 | AB14: 2975000 | AD14: =sum(AA14:AC14) -> 2975000 | AE14: 2975000 | AF14: =+OCTOBER!H20-AG14-AH14 -> 24500000 | AI14: =sum(AF14:AH14) -> 24500000 | AK14: =OCTOBER!I20-(AL14+AM14+AO14) -> 0 | AM14: 7900000 | AN14: =sum(AK14:AM14) -> 7900000 | AP14: 18800000 | AS14: =sum(AP14:AR14) -> 18800000 | AU14: =SUM(B14,G14,L14,Q14,V14,AA14,AF14,AK14,AP14) -> 173190000 | AV14: =SUM(C14,H14,M14,R14,W14,AB14,AG14,AL14,AQ14) -> 2975000 | AW14: =SUM(D14,I14,N14,S14,X14,AC14,AH14,AM14,AR14) -> 131400000 | AX14: =E14+J14+O14+T14+Y14+AD14+AI14+AN14+AS14 -> 307565000
A15: 46308 | B15: =OCTOBER!B21-C15-D15 -> 3640000 | D15: 25400000 | E15: =sum(B15:D15) -> 29040000 | J15: =sum(G15:I15) -> 0 | N15: 10980000 | O15: =sum(L15:N15) -> 10980000 | P15: - | Q15: =OCTOBER!E21-R15-S15 -> 34290000 | S15: 12580000 | T15: =sum(Q15:S15) -> 46870000 | V15: 10300000 | X15: 27310000 | Y15: =sum(V15:X15) -> 37610000 | AA15: 3800000 | AD15: =sum(AA15:AC15) -> 3800000 | AF15: =+OCTOBER!H21-AG15-AH15 -> #VALUE! | AI15: =sum(AF15:AH15) -> #VALUE! | AK15: =OCTOBER!I21-(AL15+AM15+AO15) -> 15900000 | AN15: =sum(AK15:AM15) -> 15900000 | AP15: 14720000 | AS15: =sum(AP15:AR15) -> 14720000 | AU15: =SUM(B15,G15,L15,Q15,V15,AA15,AF15,AK15,AP15) -> #VALUE! | AV15: =SUM(C15,H15,M15,R15,W15,AB15,AG15,AL15,AQ15) -> 0 | AW15: =SUM(D15,I15,N15,S15,X15,AC15,AH15,AM15,AR15) -> 76270000 | AX15: =E15+J15+O15+T15+Y15+AD15+AI15+AN15+AS15 -> #VALUE!
A16: 46309 | B16: =OCTOBER!B22-C16-D16 -> 0 | E16: =sum(B16:D16) -> 0 | J16: =sum(G16:I16) -> 0 | O16: =sum(L16:N16) -> 0 | P16: - | Q16: =OCTOBER!E22-R16-S16 -> 0 | T16: =sum(Q16:S16) -> 0 | Y16: =sum(V16:X16) -> 0 | AD16: =sum(AA16:AC16) -> 0 | AF16: =+OCTOBER!H22-AG16-AH16 -> 0 | AI16: =sum(AF16:AH16) -> 0 | AK16: =OCTOBER!I22-(AL16+AM16+AO16) -> 0 | AN16: =sum(AK16:AM16) -> 0 | AS16: =sum(AP16:AR16) -> 0 | AU16: =SUM(B16,G16,L16,Q16,V16,AA16,AF16,AK16,AP16) -> 0 | AV16: =SUM(C16,H16,M16,R16,W16,AB16,AG16,AL16,AQ16) -> 0 | AW16: =SUM(D16,I16,N16,S16,X16,AC16,AH16,AM16,AR16) -> 0 | AX16: =E16+J16+O16+T16+Y16+AD16+AI16+AN16+AS16 -> 0
A17: 46310 | B17: =OCTOBER!B23-C17-D17 -> 0 | E17: =sum(B17:D17) -> 0 | J17: =sum(G17:I17) -> 0 | O17: =sum(L17:N17) -> 0 | P17: - | Q17: =OCTOBER!E23-R17-S17 -> 0 | T17: =sum(Q17:S17) -> 0 | Y17: =sum(V17:X17) -> 0 | AD17: =sum(AA17:AC17) -> 0 | AF17: =+OCTOBER!H23-AG17-AH17 -> 0 | AI17: =sum(AF17:AH17) -> 0 | AK17: =OCTOBER!I23-(AL17+AM17+AO17) -> 0 | AN17: =sum(AK17:AM17) -> 0 | AS17: =sum(AP17:AR17) -> 0 | AU17: =SUM(B17,G17,L17,Q17,V17,AA17,AF17,AK17,AP17) -> 0 | AV17: =SUM(C17,H17,M17,R17,W17,AB17,AG17,AL17,AQ17) -> 0 | AW17: =SUM(D17,I17,N17,S17,X17,AC17,AH17,AM17,AR17) -> 0 | AX17: =E17+J17+O17+T17+Y17+AD17+AI17+AN17+AS17 -> 0
A18: 46311 | B18: =OCTOBER!B24-C18-D18 -> 0 | E18: =sum(B18:D18) -> 0 | J18: =sum(G18:I18) -> 0 | O18: =sum(L18:N18) -> 0 | P18: - | Q18: =OCTOBER!E24-R18-S18 -> 0 | T18: =sum(Q18:S18) -> 0 | Y18: =sum(V18:X18) -> 0 | AD18: =sum(AA18:AC18) -> 0 | AF18: =+OCTOBER!H24-AG18-AH18 -> 0 | AI18: =sum(AF18:AH18) -> 0 | AK18: =OCTOBER!I24-(AL18+AM18+AO18) -> 0 | AN18: =sum(AK18:AM18) -> 0 | AS18: =sum(AP18:AR18) -> 0 | AU18: =SUM(B18,G18,L18,Q18,V18,AA18,AF18,AK18,AP18) -> 0 | AV18: =SUM(C18,H18,M18,R18,W18,AB18,AG18,AL18,AQ18) -> 0 | AW18: =SUM(D18,I18,N18,S18,X18,AC18,AH18,AM18,AR18) -> 0 | AX18: =E18+J18+O18+T18+Y18+AD18+AI18+AN18+AS18 -> 0
A19: 46312 | B19: =OCTOBER!B25-C19-D19 -> 0 | E19: =sum(B19:D19) -> 0 | J19: =sum(G19:I19) -> 0 | O19: =sum(L19:N19) -> 0 | P19: - | Q19: =OCTOBER!E25-R19-S19 -> 0 | T19: =sum(Q19:S19) -> 0 | Y19: =sum(V19:X19) -> 0 | AD19: =sum(AA19:AC19) -> 0 | AF19: =+OCTOBER!H25-AG19-AH19 -> 0 | AI19: =sum(AF19:AH19) -> 0 | AK19: =OCTOBER!I25-(AL19+AM19+AO19) -> 0 | AN19: =sum(AK19:AM19) -> 0 | AS19: =sum(AP19:AR19) -> 0 | AU19: =SUM(B19,G19,L19,Q19,V19,AA19,AF19,AK19,AP19) -> 0 | AV19: =SUM(C19,H19,M19,R19,W19,AB19,AG19,AL19,AQ19) -> 0 | AW19: =SUM(D19,I19,N19,S19,X19,AC19,AH19,AM19,AR19) -> 0 | AX19: =E19+J19+O19+T19+Y19+AD19+AI19+AN19+AS19 -> 0
A20: 46313 | B20: =OCTOBER!B26-C20-D20 -> 0 | E20: =sum(B20:D20) -> 0 | J20: =sum(G20:I20) -> 0 | O20: =sum(L20:N20) -> 0 | P20: - | Q20: =OCTOBER!E26-R20-S20 -> 0 | T20: =sum(Q20:S20) -> 0 | Y20: =sum(V20:X20) -> 0 | AD20: =sum(AA20:AC20) -> 0 | AF20: =+OCTOBER!H26-AG20-AH20 -> 0 | AI20: =sum(AF20:AH20) -> 0 | AK20: =OCTOBER!I26-(AL20+AM20+AO20) -> 0 | AN20: =sum(AK20:AM20) -> 0 | AS20: =sum(AP20:AR20) -> 0 | AU20: =SUM(B20,G20,L20,Q20,V20,AA20,AF20,AK20,AP20) -> 0 | AV20: =SUM(C20,H20,M20,R20,W20,AB20,AG20,AL20,AQ20) -> 0 | AW20: =SUM(D20,I20,N20,S20,X20,AC20,AH20,AM20,AR20) -> 0 | AX20: =E20+J20+O20+T20+Y20+AD20+AI20+AN20+AS20 -> 0
A21: 46314 | B21: =OCTOBER!B27-C21-D21 -> 0 | E21: =sum(B21:D21) -> 0 | J21: =sum(G21:I21) -> 0 | O21: =sum(L21:N21) -> 0 | P21: - | Q21: =OCTOBER!E27-R21-S21 -> 0 | T21: =sum(Q21:S21) -> 0 | Y21: =sum(V21:X21) -> 0 | AD21: =sum(AA21:AC21) -> 0 | AF21: =+OCTOBER!H27-AG21-AH21 -> 0 | AI21: =sum(AF21:AH21) -> 0 | AK21: =OCTOBER!I27-(AL21+AM21+AO21) -> 0 | AN21: =sum(AK21:AM21) -> 0 | AS21: =sum(AP21:AR21) -> 0 | AU21: =SUM(B21,G21,L21,Q21,V21,AA21,AF21,AK21,AP21) -> 0 | AV21: =SUM(C21,H21,M21,R21,W21,AB21,AG21,AL21,AQ21) -> 0 | AW21: =SUM(D21,I21,N21,S21,X21,AC21,AH21,AM21,AR21) -> 0 | AX21: =E21+J21+O21+T21+Y21+AD21+AI21+AN21+AS21 -> 0
A22: 46315 | B22: =OCTOBER!B28-C22-D22 -> 0 | E22: =sum(B22:D22) -> 0 | J22: =sum(G22:I22) -> 0 | O22: =sum(L22:N22) -> 0 | P22: - | Q22: =OCTOBER!E28-R22-S22 -> 0 | T22: =sum(Q22:S22) -> 0 | Y22: =sum(V22:X22) -> 0 | AD22: =sum(AA22:AC22) -> 0 | AF22: =+OCTOBER!H28-AG22-AH22 -> 0 | AI22: =sum(AF22:AH22) -> 0 | AK22: =OCTOBER!I28-(AL22+AM22+AO22) -> 0 | AN22: =sum(AK22:AM22) -> 0 | AS22: =sum(AP22:AR22) -> 0 | AU22: =SUM(B22,G22,L22,Q22,V22,AA22,AF22,AK22,AP22) -> 0 | AV22: =SUM(C22,H22,M22,R22,W22,AB22,AG22,AL22,AQ22) -> 0 | AW22: =SUM(D22,I22,N22,S22,X22,AC22,AH22,AM22,AR22) -> 0 | AX22: =E22+J22+O22+T22+Y22+AD22+AI22+AN22+AS22 -> 0
A23: 46316 | B23: =OCTOBER!B29-C23-D23 -> 0 | E23: =sum(B23:D23) -> 0 | J23: =sum(G23:I23) -> 0 | O23: =sum(L23:N23) -> 0 | P23: - | Q23: =OCTOBER!E29-R23-S23 -> 0 | T23: =sum(Q23:S23) -> 0 | Y23: =sum(V23:X23) -> 0 | AD23: =sum(AA23:AC23) -> 0 | AF23: =+OCTOBER!H29-AG23-AH23 -> 0 | AI23: =sum(AF23:AH23) -> 0 | AK23: =OCTOBER!I29-(AL23+AM23+AO23) -> 0 | AN23: =sum(AK23:AM23) -> 0 | AS23: =sum(AP23:AR23) -> 0 | AU23: =SUM(B23,G23,L23,Q23,V23,AA23,AF23,AK23,AP23) -> 0 | AV23: =SUM(C23,H23,M23,R23,W23,AB23,AG23,AL23,AQ23) -> 0 | AW23: =SUM(D23,I23,N23,S23,X23,AC23,AH23,AM23,AR23) -> 0 | AX23: =E23+J23+O23+T23+Y23+AD23+AI23+AN23+AS23 -> 0
A24: 46317 | B24: =OCTOBER!B30-C24-D24 -> 0 | E24: =sum(B24:D24) -> 0 | J24: =sum(G24:I24) -> 0 | O24: =sum(L24:N24) -> 0 | Q24: =OCTOBER!E30-R24-S24 -> 0 | T24: =sum(Q24:S24) -> 0 | Y24: =sum(V24:X24) -> 0 | AD24: =sum(AA24:AC24) -> 0 | AF24: =+OCTOBER!H30-AG24-AH24 -> 0 | AI24: =sum(AF24:AH24) -> 0 | AK24: =OCTOBER!I30-(AL24+AM24+AO24) -> 0 | AN24: =sum(AK24:AM24) -> 0 | AS24: =sum(AP24:AR24) -> 0 | AU24: =SUM(B24,G24,L24,Q24,V24,AA24,AF24,AK24,AP24) -> 0 | AV24: =SUM(C24,H24,M24,R24,W24,AB24,AG24,AL24,AQ24) -> 0 | AW24: =SUM(D24,I24,N24,S24,X24,AC24,AH24,AM24,AR24) -> 0 | AX24: =E24+J24+O24+T24+Y24+AD24+AI24+AN24+AS24 -> 0
A25: 46318 | B25: =OCTOBER!B31-C25-D25 -> 0 | E25: =sum(B25:D25) -> 0 | J25: =sum(G25:I25) -> 0 | O25: =sum(L25:N25) -> 0 | Q25: =OCTOBER!E31-R25-S25 -> 0 | T25: =sum(Q25:S25) -> 0 | Y25: =sum(V25:X25) -> 0 | AD25: =sum(AA25:AC25) -> 0 | AF25: =+OCTOBER!H31-AG25-AH25 -> 0 | AI25: =sum(AF25:AH25) -> 0 | AK25: =OCTOBER!I31-(AL25+AM25+AO25) -> 0 | AN25: =sum(AK25:AM25) -> 0 | AS25: =sum(AP25:AR25) -> 0 | AU25: =SUM(B25,G25,L25,Q25,V25,AA25,AF25,AK25,AP25) -> 0 | AV25: =SUM(C25,H25,M25,R25,W25,AB25,AG25,AL25,AQ25) -> 0 | AW25: =SUM(D25,I25,N25,S25,X25,AC25,AH25,AM25,AR25) -> 0 | AX25: =E25+J25+O25+T25+Y25+AD25+AI25+AN25+AS25 -> 0
A26: 46319 | B26: =OCTOBER!B32-C26-D26 -> 0 | E26: =sum(B26:D26) -> 0 | J26: =sum(G26:I26) -> 0 | O26: =sum(L26:N26) -> 0 | Q26: =OCTOBER!E32-R26-S26 -> 0 | T26: =sum(Q26:S26) -> 0 | Y26: =sum(V26:X26) -> 0 | AD26: =sum(AA26:AC26) -> 0 | AF26: =+OCTOBER!H32-AG26-AH26 -> 0 | AI26: =sum(AF26:AH26) -> 0 | AK26: =OCTOBER!I32-(AL26+AM26+AO26) -> 0 | AN26: =sum(AK26:AM26) -> 0 | AS26: =sum(AP26:AR26) -> 0 | AU26: =SUM(B26,G26,L27,Q26,V26,AA26,AF26,AK26,AP26) -> 0 | AV26: =SUM(C26,H26,M27,R26,W26,AB26,AG26,AL26,AQ26) -> 0 | AW26: =SUM(D26,I26,N27,S26,X26,AC26,AH26,AM26,AR26) -> 0 | AX26: =E26+J26+O27+T26+Y26+AD26+AI26+AN26+AS26 -> 0
A27: 46320 | B27: =OCTOBER!B33-C27-D27 -> 0 | E27: =sum(B27:D27) -> 0 | J27: =sum(G27:I27) -> 0 | O27: =sum(L27:N27) -> 0 | Q27: =OCTOBER!E33-R27-S27 -> 0 | T27: =sum(Q27:S27) -> 0 | Y27: =sum(V27:X27) -> 0 | AD27: =sum(AA27:AC27) -> 0 | AF27: =+OCTOBER!H33-AG27-AH27 -> 0 | AI27: =sum(AF27:AH27) -> 0 | AK27: =OCTOBER!I33-(AL27+AM27+AO27) -> 0 | AN27: =sum(AK27:AM27) -> 0 | AS27: =sum(AP27:AR27) -> 0 | AU27: =SUM(B27,G27,L28,Q27,V27,AA27,AF27,AK27,AP27) -> 0 | AV27: =SUM(C27,H27,M28,R27,W27,AB27,AG27,AL27,AQ27) -> 0 | AW27: =SUM(D27,I27,N28,S27,X27,AC27,AH27,AM27,AR27) -> 0 | AX27: =E27+J27+O28+T27+Y27+AD27+AI27+AN27+AS27 -> 0
A28: 46321 | B28: =OCTOBER!B34-C28-D28 -> 0 | E28: =sum(B28:D28) -> 0 | J28: =sum(G28:I28) -> 0 | O28: =sum(L28:N28) -> 0 | Q28: =OCTOBER!E34-R28-S28 -> 0 | T28: =sum(Q28:S28) -> 0 | Y28: =sum(V28:X28) -> 0 | AD28: =sum(AA28:AC28) -> 0 | AF28: =+OCTOBER!H34-AG28-AH28 -> 0 | AI28: =sum(AF28:AH28) -> 0 | AK28: =OCTOBER!I34-(AL28+AM28+AO28) -> 0 | AN28: =sum(AK28:AM28) -> 0 | AS28: =sum(AP28:AR28) -> 0 | AU28: =SUM(B28,G28,L29,Q28,V28,AA28,AF28,AK28,AP28) -> 0 | AV28: =SUM(C28,H28,M29,R28,W28,AB28,AG28,AL28,AQ28) -> 0 | AW28: =SUM(D28,I28,N29,S28,X28,AC28,AH28,AM28,AR28) -> 0 | AX28: =E28+J28+O29+T28+Y28+AD28+AI28+AN28+AS28 -> 0
A29: 46322 | B29: =OCTOBER!B35-C29-D29 -> 0 | E29: =sum(B29:D29) -> 0 | J29: =sum(G29:I29) -> 0 | O29: =sum(L29:N29) -> 0 | Q29: =OCTOBER!E35-R29-S29 -> 0 | T29: =sum(Q29:S29) -> 0 | Y29: =sum(V29:X29) -> 0 | AD29: =sum(AA29:AC29) -> 0 | AF29: =+OCTOBER!H35-AG29-AH29 -> 0 | AI29: =sum(AF29:AH29) -> 0 | AK29: =OCTOBER!I35-(AL29+AM29+AO29) -> 0 | AN29: =sum(AK29:AM29) -> 0 | AS29: =sum(AP29:AR29) -> 0 | AU29: =SUM(B29,G29,L29,Q29,V29,AA29,AF29,AK29,AP29) -> 0 | AV29: =SUM(C29,H29,M29,R29,W29,AB29,AG29,AL29,AQ29) -> 0 | AW29: =SUM(D29,I29,N29,S29,X29,AC29,AH29,AM29,AR29) -> 0 | AX29: =E29+J29+O29+T29+Y29+AD29+AI29+AN29+AS29 -> 0
A30: 46323 | B30: =OCTOBER!B36-C30-D30 -> 0 | E30: =sum(B30:D30) -> 0 | J30: =sum(G30:I30) -> 0 | O30: =sum(L30:N30) -> 0 | Q30: =OCTOBER!E36-R30-S30 -> 0 | T30: =sum(Q30:S30) -> 0 | Y30: =sum(V30:X30) -> 0 | AD30: =sum(AA30:AC30) -> 0 | AF30: =+OCTOBER!H36-AG30-AH30 -> 0 | AI30: =sum(AF30:AH30) -> 0 | AK30: =OCTOBER!I36-(AL30+AM30+AO30) -> 0 | AN30: =sum(AK30:AM30) -> 0 | AS30: =sum(AP30:AR30) -> 0 | AU30: =SUM(B30,G30,L30,Q30,V30,AA30,AF30,AK30,AP30) -> 0 | AV30: =SUM(C30,H30,M30,R30,W30,AB30,AG30,AL30,AQ30) -> 0 | AW30: =SUM(D30,I30,N30,S30,X30,AC30,AH30,AM30,AR30) -> 0 | AX30: =E30+J30+O30+T30+Y30+AD30+AI30+AN30+AS30 -> 0
A31: 46324 | B31: =OCTOBER!B37-C31-D31 -> 0 | E31: =sum(B31:D31) -> 0 | J31: =sum(G31:I31) -> 0 | O31: =sum(L31:N31) -> 0 | Q31: =OCTOBER!E37-R31-S31 -> 0 | T31: =sum(Q31:S31) -> 0 | Y31: =sum(V31:X31) -> 0 | AD31: =sum(AA31:AC31) -> 0 | AF31: =+OCTOBER!H37-AG31-AH31 -> 0 | AI31: =sum(AF31:AH31) -> 0 | AK31: =OCTOBER!I37-(AL31+AM31+AO31) -> 0 | AN31: =sum(AK31:AM31) -> 0 | AS31: =sum(AP31:AR31) -> 0 | AU31: =SUM(B31,G31,L31,Q31,V31,AA31,AF31,AK31,AP31) -> 0 | AV31: =SUM(C31,H31,M31,R31,W31,AB31,AG31,AL31,AQ31) -> 0 | AW31: =SUM(D31,I31,N31,S31,X31,AC31,AH31,AM31,AR31) -> 0 | AX31: =E31+J31+O31+T31+Y31+AD31+AI31+AN31+AS31 -> 0
A32: 46325 | B32: =OCTOBER!B38-C32-D32 -> 0 | Q32: =OCTOBER!E38-R32-S32 -> 0 | AF32: =+OCTOBER!H38-AG32-AH32 -> 0 | AK32: =OCTOBER!I38-(AL32+AM32+AO32) -> 0
A33: 46326 | B33: =OCTOBER!B39-C33-D33 -> 0 | E33: =sum(B33:D33) -> 0 | J33: =sum(G33:I33) -> 0 | O33: =sum(L33:N33) -> 0 | Q33: =OCTOBER!E39-R33-S33 -> 0 | T33: =sum(Q33:S33) -> 0 | Y33: =sum(V33:X33) -> 0 | AD33: =sum(AA33:AC33) -> 0 | AF33: =+OCTOBER!H39-AG33-AH33 -> 0 | AI33: =sum(AF33:AH33) -> 0 | AK33: =OCTOBER!I39-(AL33+AM33+AO33) -> 0 | AN33: =sum(AK33:AM33) -> 0 | AS33: =sum(AP33:AR33) -> 0 | AU33: =SUM(B33,G33,L33,Q33,V33,AA33,AF33,AK33,AP33) -> 0 | AV33: =SUM(C33,H33,M33,R33,W33,AB33,AG33,AL33,AQ33) -> 0 | AW33: =SUM(D33,I33,N33,S33,X33,AC33,AH33,AM33,AR33) -> 0 | AX33: =E33+J33+O33+T33+Y33+AD33+AI33+AN33+AS33 -> 0
A34: Total Month | B34: =SUM(B3:B33) -> 455330000 | C34: =SUM(C3:C33) -> 0 | D34: =SUM(D3:D33) -> 375530000 | E34: =SUM(E3:E33) -> 830860000 | F34: =SUM(F3:F33) -> 0 | G34: =SUM(G3:G33) -> 0 | H34: =SUM(H3:H33) -> 0 | I34: =SUM(I3:I33) -> 0 | ... AY34: =SUM(AY3:AY33) -> 0
A35: Sales Mix | B35: =B34/E34 -> 0.54802253 | C35: =C34/E34 -> 0 | D35: =D34/E34 -> 0.45197747 | F35: =F34/E34 -> 0 | G35: =G34/J34 -> #DIV/0! | H35: =H34/J34 -> #DIV/0! | I35: =I34/J34 -> #DIV/0! | K35: =K34/J34 -> #DIV/0! | L35: =L34/O34 -> 0.51908259 | M35: =M34/O34 -> 0.07083233 | N35: =N34/O34 -> 0.41008508 | P35: =P34/O34 -> 0 | Q35: =Q34/T34 -> 0.60449884 | R35: =R34/T34 -> 0.012309606 | S35: =S34/T34 -> 0.38319156 | U35: =U34/T34 -> 0 | V35: =V34/Y34 -> 0.52584316 | W35: =W34/Y34 -> 0.047755443 | X35: =X34/Y34 -> 0.4264014 | Z35: =Z34/Y34 -> 0 | AA35: =AA34/AD34 -> 0.85049958 | AB35: =AB34/AD34 -> 0.13289876 | AC35: =AC34/AD34 -> 0.016601664 | AE35: =AE34/AD34 -> 0.047497849 | AF35: =AF34/AI34 -> #VALUE! | AG35: =AG34/AI34 -> #VALUE! | AH35: =AH34/AI34 -> #VALUE! | AJ35: =AJ34/AI34 -> #VALUE! | AK35: =AK34/AN34 -> 0.53460171 | AL35: =AL34/AN34 -> 0 | AM35: =AM34/AN34 -> 0.46539829 | AO35: =AO34/AN34 -> 0 | AP35: =AP34/AS34 -> 0.82473659 | AQ35: =AQ34/AS34 -> 0.016698115 | AR35: =AR34/AS34 -> 0.1585653 | AT35: =AT34/AS34 -> 0 | AU35: =AU34/AX34 -> #VALUE! | AV35: =AV34/AX34 -> #VALUE! | AW35: =AW34/AX34 -> #VALUE! | AY35: =AY34/AX34 -> #VALUE!
AU36: =sum(AU20:AU26) -> 0 | AV36: =sum(AV20:AV26) -> 0 | AW36: =sum(AW20:AW26) -> 0 | AX36: =sum(AX20:AX26) -> 0
B38: =sum(B3:B8) -> 282130000 | C38: =sum(C3:C8) -> 0 | D38: =sum(D3:D8) -> 156610000 | E38: =sum(E3:E33) -> 830860000 | G38: =sum(G3:G8) -> 0 | H38: =sum(H3:H8) -> 0 | I38: =sum(I3:I8) -> 0 | J38: =sum(J3:J8) -> 0 | L38: =sum(L3:L8) -> 299470000 | M38: =sum(M3:M8) -> 23400000 | N38: =sum(N3:N8) -> 237545000 | O38: =sum(O3:O8) -> 560415000 | Q38: =sum(Q3:Q8) -> 172530000 | R38: =sum(R3:R8) -> 0 | S38: =sum(S3:S8) -> 113100000 | T38: =sum(T3:T8) -> 285630000 | V38: =sum(V3:V8) -> 116740000 | W38: =sum(W3:W8) -> 27760000 | X38: =sum(X3:X8) -> 118645000 | Y38: =sum(Y3:Y8) -> 263145000 | AA38: =sum(AA3:AA8) -> 72926250 | AB38: =sum(AB3:AB8) -> 6752500 | AC38: =sum(AC3:AC8) -> 0 | AD38: =sum(AD3:AD8) -> 79678750 | AF38: =sum(AF3:AF8) -> 208209620 | AG38: =sum(AG3:AG8) -> 0 | AH38: =sum(AH3:AH8) -> 102790000 | AI38: =sum(AI3:AI8) -> 310999620 | AK38: =sum(AK3:AK8) -> 41500000 | AL38: =sum(AL3:AL8) -> 0 | AM38: =sum(AM3:AM8) -> 54670000 | AN38: =sum(AN3:AN8) -> 96170000 | AP38: =sum(AP3:AP8) -> 143335000 | AQ38: =sum(AQ3:AQ8) -> 5000000 | AR38: =sum(AR3:AR8) -> 27300000 | AS38: =sum(AS3:AS8) -> 175635000 | AU38: =sum(AU21:AU27) -> 0 | AV38: =sum(AV21:AV27) -> 0 | AW38: =sum(AW21:AW27) -> 0 | AX38: =sum(AX21:AX27) -> 0
B39: =B38/E38 -> 0.33956383 | C39: =C38/E38 -> 0 | D39: =D38/E38 -> 0.18849144 | G39: =G38/J38 -> #DIV/0! | H39: =H38/J38 -> #DIV/0! | I39: =I38/J38 -> #DIV/0! | L39: =L38/O38 -> 0.53437185 | M39: =M38/O38 -> 0.041754771 | N39: =N38/O38 -> 0.42387338 | Q39: =Q38/T38 -> 0.60403319 | R39: =R38/T38 -> 0 | S39: =S38/T38 -> 0.39596681 | V39: =V38/Y38 -> 0.44363374 | W39: =W38/Y38 -> 0.10549317 | X39: =X38/Y38 -> 0.45087309 | AA39: =AA38/AD38 -> 0.91525344 | AB39: =AB38/AD38 -> 0.08474656 | AC39: =AC38/AD38 -> 0 | AF39: =AF38/AI38 -> 0.66948513 | AG39: =AG38/AI38 -> 0 | AH39: =AH38/AI38 -> 0.33051487 | AK39: =AK38/AN38 -> 0.4315275 | AL39: =AL38/AN38 -> 0 | AM39: =AM38/AN38 -> 0.5684725 | AP39: =AP38/AS38 -> 0.81609588 | AQ39: =AQ38/AS38 -> 0.02846813 | AR39: =AR38/AS38 -> 0.15543599 | AU39: =AU38/AX38 -> #DIV/0! | AV39: =AV38/AX38 -> #DIV/0! | AW39: =AW38/AX38 -> #DIV/0! | AX39: =sum(AX10:AX16) -> #VALUE! | AY39: =sum(AY10:AY16) -> 0
AU40: =AU39/AX39 -> #DIV/0! | AV40: =AV39/AX39 -> #DIV/0! | AW40: =AW39/AX39 -> #DIV/0!

Sheet SEPTEMBER
B1: Total Hari | C1: 30 | G1: Copy for Closing Sales ( hanya yang di dalam kotak)
B2: Tanggal | C2: 30 | D2: ( isi dengan tanggal pengisian terakhir) | G2: =TODAY() -> 46308
G3: Total Daily Sales: | H3: =M38 -> 267673750
G4: Total MTD: | H4: =+M39 -> 12350206000 | I4: =N39 -> 0.97012733
G5: Ekspol: | H5: =M40 -> 12350206000 | I5: =M41 -> 0.97012733
G6: TL: | H6: =N39 -> 0.97012733 | I6: =100%/$C$1*C2 -> 1
B7: Sales tolong di isi oleh masing2 toko
A8: Date | B8: PI | C8: PP | D8: PS | E8: SC | F8: TP | G8: VK | H8: PIM | I8: KOKAS | J8: Icon Bali | K8: TBOS | M8: Total TB | N8: Achievement
A9: 46266 | B9: 111155000 | D9: 85430000 | E9: 56700000 | F9: 35700000 | G9: 9422250 | H9: 6000000 | I9: 12400000 | J9: 25940000 | K9: 0 | M9: =SUM(B9:L9) -> 342747250
A10: 46267 | B10: 34040000 | D10: 85095000 | E10: 59880000 | F10: 41585000 | G10: 9633750 | H10: 33710000 | I10: 0 | J10: 13900000 | K10: 9800000 | M10: =SUM(B10:L10) -> 287643750
A11: 46268 | B11: 42770000 | D11: 41170000 | E11: 52440000 | F11: 25690000 | G11: 3612500 | H11: 60200000 | I11: 123670000 | J11: 33860000 | K11: 14400000 | M11: =SUM(B11:L11) -> 397812500
A12: 46269 | B12: 139300000 | D12: 168925000 | E12: 227390000 | F12: 0 | G12: 37751250 | H12: 91450000 | I12: 133100000 | J12: 14200000 | K12: 0 | M12: =SUM(B12:L12) -> 812116250
A13: 46270 | B13: 92310000 | D13: 61525000 | E13: 187740000 | F13: 39550000 | G13: 20542500 | H13: 157760000 | I13: 53720000 | J13: 69500000 | K13: 0 | M13: =SUM(B13:L13) -> 682647500
A14: 46271 | B14: 158540000 | D14: 191835000 | E14: 260470000 | F14: 53440000 | G14: 9170000 | H14: 40960000 | I14: 65200000 | J14: 67220000 | K14: 0 | M14: =SUM(B14:L14) -> 846835000
A15: 46272 | B15: 14250000 | D15: 56975000 | E15: 59560000 | F15: 195190000 | G15: 3378750 | H15: 40400000 | I15: 0 | J15: 5800000 | K15: 61900000 | M15: =SUM(B15:L15) -> 437453750
A16: 46273 | B16: 46520000 | D16: 46090000 | E16: 50340000 | F16: 19865000 | G16: 7500000 | H16: 33750000 | I16: =5110000+31320000 -> 36430000 | J16: 35500000 | K16: 5525000 | M16: =SUM(B16:L16) -> 281520000
A17: 46274 | B17: 40070000 | D17: - | E17: 47280000 | F17: 26930000 | G17: 0 | H17: 52750000 | I17: =82030000+107460000 -> 189490000 | J17: 43400000 | K17: 6885000 | M17: =SUM(B17:K17) -> 406805000
A18: 46275 | B18: 51865000 | D18: 80820000 | E18: 74650000 | F18: 37850000 | G18: 52562500 | H18: 61565000 | I18: 0 | J18: 20100000 | K18: 31415000 | M18: =SUM(B18:K18) -> 410827500
A19: 46276 | B19: 35800000 | D19: 51000000 | E19: 51390000 | F19: 33000000 | G19: 10950000 | H19: 14400000 | I19: 29100000 | J19: 45000000 | K19: 0 | M19: =SUM(B19:K19) -> 270640000
A20: 46277 | B20: 95755000 | D20: 100110000 | E20: 96700000 | F20: 47685000 | G20: 25655000 | H20: 22080000 | I20: 52500000 | J20: 18850000 | K20: 0 | M20: =SUM(B20:K20) -> 459335000
A21: 46278 | B21: 43240000 | D21: 66000000 | E21: 86850000 | F21: 49700000 | G21: 0 | H21: 74020000 | I21: 48360000 | J21: 0 | K21: 0 | M21: =SUM(B21:K21) -> 368170000
A22: 46279 | B22: 16410000 | D22: 6400000 | E22: 28240000 | F22: 50140000 | G22: 23843750 | H22: 27200000 | I22: 5200000 | J22: 0 | K22: 26800000 | M22: =SUM(B22:K22) -> 184233750
A23: 46280 | B23: 91885000 | D23: 33520000 | E23: 37530000 | F23: 18040000 | G23: 5880000 | H23: 29500000 | I23: 7920000 | J23: 11300000 | K23: 11600000 | M23: =SUM(B23:K23) -> 247175000
A24: 46281 | B24: 63870000 | D24: 73950000 | E24: 98990000 | F24: 76065000 | G24: 4380000 | H24: 36200000 | I24: 22600000 | J24: 2250000 | K24: 5880000 | M24: =SUM(B24:K24) -> 384185000
A25: 46282 | B25: 43945000 | D25: 105150000 | E25: 64050000 | F25: 37750000 | G25: 0 | H25: 60510000 | I25: 16500000 | J25: 5800000 | K25: 13432000 | M25: =SUM(B25:K25) -> 347137000
A26: 46283 | B26: 46280000 | D26: 35065000 | E26: 89680000 | F26: 36350000 | G26: 6627500 | H26: 42100000 | I26: 56300000 | J26: 50250000 | K26: 16500000 | M26: =SUM(B26:K26) -> 379152500
A27: 46284 | B27: 63150000 | D27: 136930000 | E27: 20900000 | F27: 192540000 | G27: 5440000 | H27: 64580000 | I27: 58765000 | J27: 23800000 | K27: 0 | M27: =SUM(B27:K27) -> 566105000
A28: 46285 | B28: 65745000 | D28: 94907500 | E28: 105090000 | F28: 94300000 | G28: 15406250 | H28: 63500000 | I28: 46790000 | J28: 40700000 | K28: 0 | M28: =SUM(B28:K28) -> 526438750
A29: 46286 | B29: 63270000 | D29: 108520000 | E29: 56350000 | F29: 77510000 | G29: 3166250 | H29: 67610000 | I29: 11360000 | J29: 20850000 | K29: 0 | M29: =SUM(B29:K29) -> 408636250
... A31: 46288 | B31: 27950000 | D31: 33900000 | E31: 35130000 | F31: 42570000 | G31: 3808000 | H31: 44160000 | I31: 7000000 | J31: 15100000 | K31: 0 | M31: =SUM(B31:K31) -> 209618000
A32: 46289 | B32: - | D32: 47020000 | E32: 32840000 | F32: 46540000 | G32: 11760000 | H32: 40900000 | I32: 21650000 | J32: 79710000 | K32: 14500000 | M32: =SUM(B32:K32) -> 294920000
A33: 46290 | B33: 77760000 | D33: 33040000 | E33: 64270000 | F33: 46650000 | G33: 22158750 | H33: 21610000 | I33: 10300000 | J33: 17860000 | K33: 14500000 | M33: =SUM(B33:K33) -> 308148750
A34: 46291 | B34: 92870000 | D34: 70920000 | E34: 145105000 | F34: 124970000 | G34: 40835000 | H34: 102900000 | I34: 18465000 | J34: 57930000 | K34: 0 | M34: =SUM(B34:K34) -> 653995000
A35: 46292 | B35: 108560000 | D35: 95680000 | E35: 141430000 | F35: 76350000 | G35: 53625000 | H35: 42475000 | I35: 39000000 | J35: 13600000 | K35: 0 | M35: =SUM(B35:K35) -> 570720000
A36: 46293 | B36: 36640000 | D36: 17000000 | E36: 21700000 | F36: 53700000 | G36: 9698500 | H36: 43100000 | I36: 0 | J36: 0 | K36: 59745000 | M36: =SUM(B36:K36) -> 241583500
A37: 46294 | B37: 54640000 | D37: 38600000 | E37: 70090000 | F37: 40623500 | G37: 29608000 | H37: 75100000 | I37: 14850000 | J37: 24200000 | K37: 6660000 | M37: =SUM(B37:K37) -> 354371500
A38: 46295 | B38: 26650000 | D38: 43030000 | E38: 36440000 | F38: 62310000 | G38: 8723750 | H38: 3150000 | I38: 0 | J38: 57610000 | K38: 29760000 | M38: =SUM(B38:K38) -> 267673750
A39: Total Month | B39: =SUM(B9:B38) -> 1870810000 | C39: =SUM(C9:C38) -> 0 | D39: =SUM(D9:D38) -> 2052717500 | E39: =SUM(E9:E38) -> 2452325000 | F39: =SUM(F9:F38) -> 1713843500 | G39: =SUM(G9:G38) -> 437583000 | H39: =SUM(H9:H38) -> 1481940000 | I39: =SUM(I9:I38) -> 1092270000 | ... K39: =SUM(K9:K38) -> 352202000 | M39: =SUM(M9:M38) -> 12350206000 | N39: =M39/M42 -> 0.97012733
A40: Expol | B40: =B39*$C$1/$C$2 -> 1870810000 | C40: =C39*$C$1/$C$2 -> 0 | D40: =D39*$C$1/$C$2 -> 2052717500 | E40: =E39*$C$1/$C$2 -> 2452325000 | F40: =F39*$C$1/$C$2 -> 1713843500 | G40: =G39/C2*C1 -> 437583000 | H40: =H39*$C$1/$C$2 -> 1481940000 | I40: =I39*$C$1/$C$2 -> 1092270000 | J40: =J39*$C$1/$C$2 -> 896515000 | K40: =K39*$C$1/$C$2 -> 352202000 | L40: =L39*$C$1/$C$2 -> 0 | M40: =SUM(B40:L40) -> 12350206000
A41: % Expol | B41: =B40/B42 -> 1.0690343 | C41: =C40/C42 -> #DIV/0! | D41: =D40/D42 -> 0.821087 | E41: =E40/E42 -> 0.95235922 | F41: =F40/F42 -> 0.95213528 | G41: =G40/G42 -> 0.875166 | H41: =H40/H42 -> 1.0047051 | I41: =I40/I42 -> 1.0402571 | ... K41: =K40/K42 -> 1.0656641 | M41: =M40/M42 -> 0.97012733
...

Sheet September Detail
A1: Date | B1: PI | G1: PP | L1: PS | Q1: SC | V1: TP | AA1: VK | AF1: PIM | AK1: KOKAS | AP1: Icon Bali | AU1: Total
B2: Walk In | C2: CT | D2: Appointments | E2: Total Store | F2: Social Media | G2: Walk In | H2: CT | I2: Appointments | J2: Total Store | K2: Social Media | L2: Walk In | M2: CT | N2: Appointments | O2: Total Store | P2: Social Media | Q2: Walk In | R2: CT | S2: Appointments | T2: Total Store | U2: Social Media | V2: Walk In | W2: CT | X2: Appointments | Y2: Total Store | Z2: Social Media | AA2: Walk In | AB2: CT | AC2: Appointments | AD2: Total Store | AE2: Social Media | AF2: Walk In | AG2: CT | AH2: Appointments | AI2: Total Store | AJ2: Social Media | AK2: Walk In | AL2: CT | AM2: Appointments | AN2: Total Store | AO2: Social Media | AP2: Walk In | AQ2: CT | AR2: Appointments | AS2: Total Store | AT2: Social Media | AU2: Walk In | AV2: CT | AW2: Appointments | AX2: Total Store | AY2: Social Media
A3: 46266 | B3: =SEPTEMBER!B9-C3-D3 -> 92255000 | D3: 18900000 | E3: =sum(B3:D3) -> 111155000 | J3: =sum(G3:I3) -> 0 | L3: 63620000 | M3: - | N3: 21810000 | O3: =sum(L3:N3) -> 85430000 | P3: - | Q3: =SEPTEMBER!E9-R3-S3 -> 28900000 | S3: 27800000 | T3: =sum(Q3:S3) -> 56700000 | V3: 35700000 | Y3: =sum(V3:X3) -> 35700000 | AA3: 9422250 | AD3: =sum(AA3:AC3) -> 9422250 | AF3: =+SEPTEMBER!H9-(AG3+AH3) -> 6000000 | AG3: 0 | AH3: 0 | AI3: =sum(AF3:AH3) -> 6000000 | AK3: =+SEPTEMBER!I9-(AL3+AM3+AO3) -> 0 | AM3: 12400000 | AN3: =sum(AK3:AM3) -> 12400000 | AP3: 25940000 | AS3: =sum(AP3:AR3) -> 25940000 | AU3: =SUM(B3,G3,L3,Q3,V3,AA3,AF3,AK3,AP3) -> 261837250 | AV3: =SUM(C3,H3,M3,R3,W3,AB3,AG3,AL3,AQ3) -> 0 | AW3: =SUM(D3,I3,N3,S3,X3,AC3,AH3,AM3,AR3) -> 80910000 | AX3: =E3+J3+O3+T3+Y3+AD3+AI3+AN3+AS3 -> 342747250
A4: 46267 | B4: =SEPTEMBER!B10-C4-D4 -> 14940000 | D4: 19100000 | E4: =sum(B4:D4) -> 34040000 | J4: =sum(G4:I4) -> 0 | L4: 75150000 | M4: - | N4: 9945000 | O4: =sum(L4:N4) -> 85095000 | P4: - | Q4: =SEPTEMBER!E10-R4-S4 -> 44780000 | S4: 15100000 | T4: =sum(Q4:S4) -> 59880000 | V4: 14690000 | X4: 26895000 | Y4: =sum(V4:X4) -> 41585000 | AA4: 9633750 | AD4: =sum(AA4:AC4) -> 9633750 | AF4: =+SEPTEMBER!H10-(AG4+AH4) -> 27910000 | AG4: 0 | AH4: 5800000 | AI4: =sum(AF4:AH4) -> 33710000 | AK4: =+SEPTEMBER!I10-(AL4+AM4) -> 0 | AL4: 0 | AM4: 0 | AN4: =sum(AK4:AM4) -> 0 | AP4: 13900000 | AS4: =sum(AP4:AR4) -> 13900000 | AU4: =SUM(B4,G4,L4,Q4,V4,AA4,AF4,AK4,AP4) -> 201003750 | AV4: =SUM(C4,H4,M4,R4,W4,AB4,AG4,AL4,AQ4) -> 0 | AW4: =SUM(D4,I4,N4,S4,X4,AC4,AH4,AM4,AR4) -> 76840000 | AX4: =E4+J4+O4+T4+Y4+AD4+AI4+AN4+AS4 -> 277843750
A5: 46268 | B5: =SEPTEMBER!B11-C5-D5 -> 33870000 | D5: 8900000 | E5: =sum(B5:D5) -> 42770000 | J5: =sum(G5:I5) -> 0 | L5: 27070000 | M5: 14100000 | N5: - | O5: =sum(L5:N5) -> 41170000 | P5: - | Q5: =SEPTEMBER!E11-R5-S5 -> 47050000 | S5: 5390000 | T5: =sum(Q5:S5) -> 52440000 | V5: 25690000 | Y5: =sum(V5:X5) -> 25690000 | AA5: 3612500 | AD5: =sum(AA5:AC5) -> 3612500 | AF5: =+SEPTEMBER!H11-(AG5+AH5) -> 42450000 | AG5: 0 | AH5: 17750000 | AI5: =sum(AF5:AH5) -> 60200000 | AK5: =+SEPTEMBER!I11-(AL5+AM5) -> 113510000 | AM5: =5400000+4760000 -> 10160000 | AN5: =sum(AK5:AM5) -> 123670000 | AP5: 33860000 | AS5: =sum(AP5:AR5) -> 33860000 | AU5: =SUM(B5,G5,L5,Q5,V5,AA5,AF5,AK5,AP5) -> 327112500 | AV5: =SUM(C5,H5,M5,R5,W5,AB5,AG5,AL5,AQ5) -> 14100000 | AW5: =SUM(D5,I5,N5,S5,X5,AC5,AH5,AM5,AR5) -> 42200000 | AX5: =E5+J5+O5+T5+Y5+AD5+AI5+AN5+AS5 -> 383412500
A6: 46269 | B6: =SEPTEMBER!B12-C6-D6 -> 6800000 | D6: 132500000 | E6: =sum(B6:D6) -> 139300000 | J6: =sum(G6:I6) -> 0 | L6: 21925000 | M6: - | N6: 147000000 | O6: =sum(L6:N6) -> 168925000 | P6: - | Q6: =SEPTEMBER!E12-R6-S6 -> 43180000 | R6: 74500000 | S6: 109710000 | T6: =sum(Q6:S6) -> 227390000 | Y6: =sum(V6:X6) -> 0 | AA6: 37751250 | AD6: =sum(AA6:AC6) -> 37751250 | AF6: =+SEPTEMBER!H12-(AG6+AH6) -> -600000 | AG6: 42050000 | AH6: 50000000 | AI6: =sum(AF6:AH6) -> 91450000 | AK6: =+SEPTEMBER!I12-(AL6+AM6) -> 15100000 | AL6: 60000000 | AM6: 58000000 | AN6: =sum(AK6:AM6) -> 133100000 | AP6: 14200000 | AS6: =sum(AP6:AR6) -> 14200000 | AU6: =SUM(B6,G6,L6,Q6,V6,AA6,AF6,AK6,AP6) -> 138356250 | AV6: =SUM(C6,H6,M6,R6,W6,AB6,AG6,AL6,AQ6) -> 176550000 | AW6: =SUM(D6,I6,N6,S6,X6,AC6,AH6,AM6,AR6) -> 497210000 | AX6: =E6+J6+O6+T6+Y6+AD6+AI6+AN6+AS6 -> 812116250
A7: 46270 | B7: =SEPTEMBER!B13-C7-D7 -> 39110000 | D7: 53200000 | E7: =sum(B7:D7) -> 92310000 | J7: =sum(G7:I7) -> 0 | L7: 23015000 | M7: - | N7: 38510000 | O7: =sum(L7:N7) -> 61525000 | P7: - | Q7: =SEPTEMBER!E13-R7-S7 -> 98940000 | S7: 88800000 | T7: =sum(Q7:S7) -> 187740000 | V7: 16650000 | X7: 22900000 | Y7: =sum(V7:X7) -> 39550000 | AA7: 13612500 | AB7: 6930000 | AD7: =sum(AA7:AC7) -> 20542500 | AF7: =+SEPTEMBER!H13-(AG7+AH7) -> 157760000 | AG7: 0 | AH7: 0 | AI7: =sum(AF7:AH7) -> 157760000 | AK7: 8220000 | AM7: 45500000 | AN7: =sum(AK7:AM7) -> 53720000 | AO7: 0 | AP7: 49350000 | AQ7: 0 | AR7: 20150000 | AS7: =sum(AP7:AR7) -> 69500000 | AU7: =SUM(B7,G7,L7,Q7,V7,AA7,AF7,AK7,AP7) -> 406657500 | AV7: =SUM(C7,H7,M7,R7,W7,AB7,AG7,AL7,AQ7) -> 6930000 | AW7: =SUM(D7,I7,N7,S7,X7,AC7,AH7,AM7,AR7) -> 269060000 | AX7: =E7+J7+O7+T7+Y7+AD7+AI7+AN7+AS7 -> 682647500
A8: 46271 | B8: =SEPTEMBER!B14-C8-D8 -> 58640000 | D8: 99900000 | E8: =sum(B8:D8) -> 158540000 | J8: =sum(G8:I8) -> 0 | L8: 191835000 | M8: - | N8: - | O8: =sum(L8:N8) -> 191835000 | P8: - | Q8: =SEPTEMBER!E14-R8-S8 -> 91330000 | R8: 42400000 | S8: 126740000 | T8: =sum(Q8:S8) -> 260470000 | V8: =SEPTEMBER!F14-X8 -> 21600000 | X8: 31840000 | Y8: =sum(V8:X8) -> 53440000 | AA8: 9170000 | AD8: =sum(AA8:AC8) -> 9170000 | AF8: =+SEPTEMBER!H14-(AG8+AH8) -> 11960000 | AG8: 0 | AH8: 29000000 | AI8: =sum(AF8:AH8) -> 40960000 | AK8: =+SEPTEMBER!I14-(AL8+AM8) -> 36500000 | AM8: =14200000+14500000 -> 28700000 | AN8: =sum(AK8:AM8) -> 65200000 | AP8: 43670000 | AR8: 23550000 | AS8: =sum(AP8:AR8) -> 67220000 | AU8: =SUM(B8,G8,L8,Q8,V8,AA8,AF8,AK8,AP8) -> 464705000 | AV8: =SUM(C8,H8,M8,R8,W8,AB8,AG8,AL8,AQ8) -> 42400000 | AW8: =SUM(D8,I8,N8,S8,X8,AC8,AH8,AM8,AR8) -> 339730000 | AX8: =E8+J8+O8+T8+Y8+AD8+AI8+AN8+AS8 -> 846835000
A9: 46272 | B9: =SEPTEMBER!B15-C9-D9 -> 7850000 | D9: 6400000 | E9: =sum(B9:D9) -> 14250000 | J9: =sum(G9:I9) -> 0 | L9: 49375000 | M9: - | N9: 7600000 | O9: =sum(L9:N9) -> 56975000 | P9: - | Q9: =SEPTEMBER!E15-R9-S9 -> 37500000 | R9: 14500000 | S9: 7560000 | T9: =sum(Q9:S9) -> 59560000 | X9: 195190000 | Y9: =sum(V9:X9) -> 195190000 | AA9: 3378750 | AD9: =sum(AA9:AC9) -> 3378750 | AF9: =+SEPTEMBER!H15-(AG9+AH9) -> 30400000 | AG9: 0 | AH9: 10000000 | AI9: =sum(AF9:AH9) -> 40400000 | AK9: =+SEPTEMBER!I15-(AL9+AM9) -> 0 | AN9: =sum(AK9:AM9) -> 0 | AP9: 5800000 | AS9: =sum(AP9:AR9) -> 5800000 | AU9: =SUM(B9,G9,L9,Q9,V9,AA9,AF9,AK9,AP9) -> 134303750 | AV9: =SUM(C9,H9,M9,R9,W9,AB9,AG9,AL9,AQ9) -> 14500000 | AW9: =SUM(D9,I9,N9,S9,X9,AC9,AH9,AM9,AR9) -> 226750000 | AX9: =E9+J9+O9+T9+Y9+AD9+AI9+AN9+AS9 -> 375553750
A10: 46273 | B10: =SEPTEMBER!B16-C10-D10 -> 20640000 | D10: 25880000 | E10: =sum(B10:D10) -> 46520000 | F10: =4800000+13100000 -> 17900000 | J10: =sum(G10:I10) -> 0 | L10: 46090000 | M10: - | N10: - | O10: =sum(L10:N10) -> 46090000 | P10: - | Q10: =SEPTEMBER!E16-R10-S10 -> 22740000 | R10: 14500000 | S10: 13100000 | T10: =sum(Q10:S10) -> 50340000 | V10: 19865000 | Y10: =sum(V10:X10) -> 19865000 | AA10: 7500000 | AD10: =sum(AA10:AC10) -> 7500000 | AF10: =+SEPTEMBER!H16-(AG10+AH10) -> 23450000 | AG10: 0 | AH10: 10300000 | AI10: =sum(AF10:AH10) -> 33750000 | AK10: =+SEPTEMBER!I16-(AL10+AM10) -> 31320000 | AM10: 5110000 | AN10: =sum(AK10:AM10) -> 36430000 | AP10: 10300000 | AR10: 25200000 | AS10: =sum(AP10:AR10) -> 35500000 | AU10: =SUM(B10,G10,L10,Q10,V10,AA10,AF10,AK10,AP10) -> 181905000 | AV10: =SUM(C10,H10,M10,R10,W10,AB10,AG10,AL10,AQ10) -> 14500000 | AW10: =SUM(D10,I10,N10,S10,X10,AC10,AH10,AM10,AR10) -> 79590000 | AX10: =E10+J10+O10+T10+Y10+AD10+AI10+AN10+AS10 -> 275995000
A11: 46274 | B11: =SEPTEMBER!B17-C11-D11 -> 5200000 | D11: 34870000 | E11: =sum(B11:D11) -> 40070000 | J11: =sum(G11:I11) -> 0 | L11: - | M11: - | N11: - | O11: =sum(L11:N11) -> 0 | P11: - | Q11: =SEPTEMBER!E17-R11-S11 -> 26300000 | R11: 2700000 | S11: 18280000 | T11: =sum(Q11:S11) -> 47280000 | X11: 26930000 | Y11: =sum(V11:X11) -> 26930000 | AA11: 0 | AB11: 0 | AC11: 0 | AD11: =sum(AA11:AC11) -> 0 | AF11: =+SEPTEMBER!H17-(AG11+AH11) -> 12350000 | AG11: 0 | AH11: 40400000 | AI11: =sum(AF11:AH11) -> 52750000 | AK11: =+SEPTEMBER!I17-(AL11+AM11) -> 160790000 | AM11: =16500000+12200000 -> 28700000 | AN11: =sum(AK11:AM11) -> 189490000 | AP11: 8600000 | AQ11: 0 | AR11: 34800000 | AS11: =sum(AP11:AR11) -> 43400000 | AU11: =SUM(B11,G11,L11,Q11,V11,AA11,AF11,AK11,AP11) -> 213240000 | AV11: =SUM(C11,H11,M11,R11,W11,AB11,AG11,AL11,AQ11) -> 2700000 | AW11: =SUM(D11,I11,N11,S11,X11,AC11,AH11,AM11,AR11) -> 183980000 | AX11: =E11+J11+O11+T11+Y11+AD11+AI11+AN11+AS11 -> 399920000
A12: 46275 | B12: =SEPTEMBER!B18-C12-D12 -> 32265000 | D12: 19600000 | E12: =sum(B12:D12) -> 51865000 | J12: =sum(G12:I12) -> 0 | L12: 59680000 | M12: 9800000 | N12: 11340000 | O12: =sum(L12:N12) -> 80820000 | P12: - | Q12: =SEPTEMBER!E18-R12-S12 -> 42700000 | S12: 31950000 | T12: =sum(Q12:S12) -> 74650000 | V12: =SEPTEMBER!F18-X12 -> 23000000 | X12: 14850000 | Y12: =sum(V12:X12) -> 37850000 | AA12: 47162500 | AB12: 5400000 | AD12: 52562500 | AF12: =+SEPTEMBER!H18-(AG12+AH12) -> 10065000 | AG12: 9800000 | AH12: 41700000 | AI12: =sum(AF12:AH12) -> 61565000 | AK12: =+SEPTEMBER!I18-(AL12+AM12) -> 0 | AN12: =sum(AK12:AM12) -> 0 | AP12: 7900000 | AR12: 12200000 | AS12: =sum(AP12:AR12) -> 20100000 | AU12: =SUM(B12,G12,L12,Q12,V12,AA12,AF12,AK12,AP12) -> 222772500 | AV12: =SUM(C12,H12,M12,R12,W12,AB12,AG12,AL12,AQ12) -> 25000000 | AW12: =SUM(D12,I12,N12,S12,X12,AC12,AH12,AM12,AR12) -> 131640000 | AX12: =E12+J12+O12+T12+Y12+AD12+AI12+AN12+AS12 -> 379412500
A13: 46276 | B13: =SEPTEMBER!B19-C13-D13 -> 7600000 | D13: 28200000 | E13: =sum(B13:D13) -> 35800000 | J13: =sum(G13:I13) -> 0 | L13: 51000000 | M13: - | N13: - | O13: =sum(L13:N13) -> 51000000 | P13: - | Q13: =SEPTEMBER!E19-R13-S13 -> 24700000 | S13: 26690000 | T13: =sum(Q13:S13) -> 51390000 | V13: 16500000 | X13: 16500000 | Y13: =sum(V13:X13) -> 33000000 | AA13: 10950000 | AD13: =sum(AA13:AC13) -> 10950000 | AF13: =+SEPTEMBER!H19-(AG13+AH13) -> 14400000 | AG13: 0 | AH13: 0 | AI13: =sum(AF13:AH13) -> 14400000 | AK13: =+SEPTEMBER!I19-(AL13+AM13) -> 14200000 | AM13: 14900000 | AN13: =sum(AK13:AM13) -> 29100000 | AP13: 45000000 | AS13: =sum(AP13:AR13) -> 45000000 | AU13: =SUM(B13,G13,L13,Q13,V13,AA13,AF13,AK13,AP13) -> 184350000 | AV13: =SUM(C13,H13,M13,R13,W13,AB13,AG13,AL13,AQ13) -> 0 | AW13: =SUM(D13,I13,N13,S13,X13,AC13,AH13,AM13,AR13) -> 86290000 | AX13: =E13+J13+O13+T13+Y13+AD13+AI13+AN13+AS13 -> 270640000
A14: 46277 | B14: =SEPTEMBER!B20-C14-D14 -> 49960000 | D14: 45795000 | E14: =sum(B14:D14) -> 95755000 | J14: =sum(G14:I14) -> 0 | L14: 73410000 | M14: 15200000 | N14: 11500000 | O14: =sum(L14:N14) -> 100110000 | P14: - | Q14: =SEPTEMBER!E20-R14-S14 -> 43750000 | S14: 52950000 | T14: =sum(Q14:S14) -> 96700000 | V14: 47685000 | Y14: =sum(V14:X14) -> 47685000 | AA14: 25655000 | AD14: =sum(AA14:AC14) -> 25655000 | AF14: =+SEPTEMBER!H20-(AG14+AH14) -> 22080000 | AG14: 0 | AH14: 0 | AI14: =sum(AF14:AH14) -> 22080000 | AK14: =14200000+9600000 -> 23800000 | AM14: =14500000+14200000 -> 28700000 | AN14: =sum(AK14:AM14) -> 52500000 | AP14: 5800000 | AR14: 13050000 | AS14: =sum(AP14:AR14) -> 18850000 | AU14: =SUM(B14,G14,L14,Q14,V14,AA14,AF14,AK14,AP14) -> 292140000 | AV14: =SUM(C14,H14,M14,R14,W14,AB14,AG14,AL14,AQ14) -> 15200000 | AW14: =SUM(D14,I14,N14,S14,X14,AC14,AH14,AM14,AR14) -> 151995000 | AX14: =E14+J14+O14+T14+Y14+AD14+AI14+AN14+AS14 -> 459335000
A15: 46278 | B15: =SEPTEMBER!B21-C15-D15 -> 7250000 | D15: 35990000 | E15: =sum(B15:D15) -> 43240000 | J15: =sum(G15:I15) -> 0 | L15: 38300000 | M15: 11200000 | N15: 16500000 | O15: =sum(L15:N15) -> 66000000 | P15: - | Q15: =SEPTEMBER!E21-R15-S15 -> 52250000 | S15: 34600000 | T15: =sum(Q15:S15) -> 86850000 | V15: 35500000 | X15: 14200000 | Y15: =sum(V15:X15) -> 49700000 | AA15: - | AB15: - | AC15: - | AD15: =sum(AA15:AC15) -> 0 | AF15: =+SEPTEMBER!H21-(AG15+AH15) -> 49320000 | AG15: 0 | AH15: 24700000 | AI15: =sum(AF15:AH15) -> 74020000 | AK15: =48360000-AM15 -> 26460000 | AM15: =10300000+11600000 -> 21900000 | AN15: =sum(AK15:AM15) -> 48360000 | AP15: 0 | AQ15: 0 | AR15: 0 | AS15: =sum(AP15:AR15) -> 0 | AU15: =SUM(B15,G15,L15,Q15,V15,AA15,AF15,AK15,AP15) -> 209080000 | AV15: =SUM(C15,H15,M15,R15,W15,AB15,AG15,AL15,AQ15) -> 11200000 | AW15: =SUM(D15,I15,N15,S15,X15,AC15,AH15,AM15,AR15) -> 147890000 | AX15: =E15+J15+O15+T15+Y15+AD15+AI15+AN15+AS15 -> 368170000
A16: 46279 | B16: =SEPTEMBER!B22-C16-D16 -> 8610000 | D16: 7800000 | E16: =sum(B16:D16) -> 16410000 | J16: =sum(G16:I16) -> 0 | L16: - | M16: - | N16: 6400000 | O16: =sum(L16:N16) -> 6400000 | P16: - | Q16: =SEPTEMBER!E22-R16-S16 -> 18440000 | S16: 9800000 | T16: =sum(Q16:S16) -> 28240000 | V16: 50140000 | Y16: =sum(V16:X16) -> 50140000 | AA16: 18340000 | AB16: 5503750 | AD16: 23843750 | AF16: =+SEPTEMBER!H22-(AG16+AH16) -> 27200000 | AG16: 0 | AH16: 0 | AI16: =sum(AF16:AH16) -> 27200000 | AK16: =+SEPTEMBER!I22-(AL16+AM16) -> 0 | AM16: 5200000 | AN16: =sum(AK16:AM16) -> 5200000 | AP16: 0 | AR16: 0 | AS16: =sum(AP16:AR16) -> 0 | AU16: =SUM(B16,G16,L16,Q16,V16,AA16,AF16,AK16,AP16) -> 122730000 | AV16: =SUM(C16,H16,M16,R16,W16,AB16,AG16,AL16,AQ16) -> 5503750 | AW16: =SUM(D16,I16,N16,S16,X16,AC16,AH16,AM16,AR16) -> 29200000 | AX16: =E16+J16+O16+T16+Y16+AD16+AI16+AN16+AS16 -> 157433750
A17: 46280 | B17: =SEPTEMBER!B23-C17-D17 -> 30835000 | D17: 61050000 | E17: =sum(B17:D17) -> 91885000 | J17: =sum(G17:I17) -> 0 | L17: 33520000 | M17: - | N17: - | O17: =sum(L17:N17) -> 33520000 | P17: - | Q17: =SEPTEMBER!E23-R17-S17 -> 23650000 | S17: 13880000 | T17: =sum(Q17:S17) -> 37530000 | V17: 18040000 | Y17: =sum(V17:X17) -> 18040000 | AA17: 5880000 | AD17: =sum(AA17:AC17) -> 5880000 | AF17: =+SEPTEMBER!H23-(AG17+AH17) -> 7000000 | AG17: 6000000 | AH17: 16500000 | AI17: =sum(AF17:AH17) -> 29500000 | AK17: =+SEPTEMBER!I23-(AL17+AM17) -> 7920000 | AN17: =sum(AK17:AM17) -> 7920000 | AP17: 11300000 | AS17: =sum(AP17:AR17) -> 11300000 | AU17: =SUM(B17,G17,L17,Q17,V17,AA17,AF17,AK17,AP17) -> 138145000 | AV17: =SUM(C17,H17,M17,R17,W17,AB17,AG17,AL17,AQ17) -> 6000000 | AW17: =SUM(D17,I17,N17,S17,X17,AC17,AH17,AM17,AR17) -> 91430000 | AX17: =E17+J17+O17+T17+Y17+AD17+AI17+AN17+AS17 -> 235575000
A18: 46281 | B18: =SEPTEMBER!B24-C18-D18 -> 14670000 | D18: 49200000 | E18: =sum(B18:D18) -> 63870000 | J18: =sum(G18:I18) -> 0 | L18: 15400000 | M18: - | N18: 58550000 | O18: =sum(L18:N18) -> 73950000 | P18: - | Q18: =SEPTEMBER!E24-R18-S18 -> 38160000 | R18: 14500000 | S18: 46330000 | T18: =sum(Q18:S18) -> 98990000 | V18: 76065000 | Y18: =sum(V18:X18) -> 76065000 | AA18: 4380000 | AD18: =sum(AA18:AC18) -> 4380000 | AF18: =+SEPTEMBER!H24-(AG18+AH18) -> 0 | AG18: 0 | AH18: 36200000 | AI18: =sum(AF18:AH18) -> 36200000 | AK18: 8100000 | AM18: 14500000 | AN18: =sum(AK18:AM18) -> 22600000 | AR18: 2250000 | AS18: =sum(AP18:AR18) -> 2250000 | AU18: =SUM(B18,G18,L18,Q18,V18,AA18,AF18,AK18,AP18) -> 156775000 | AV18: =SUM(C18,H18,M18,R18,W18,AB18,AG18,AL18,AQ18) -> 14500000 | AW18: =SUM(D18,I18,N18,S18,X18,AC18,AH18,AM18,AR18) -> 207030000 | AX18: =E18+J18+O18+T18+Y18+AD18+AI18+AN18+AS18 -> 378305000
A19: 46282 | B19: =SEPTEMBER!B25-C19-D19 -> 27540000 | D19: 16405000 | E19: =sum(B19:D19) -> 43945000 | J19: =sum(G19:I19) -> 0 | L19: 50350000 | M19: - | N19: 54800000 | O19: =sum(L19:N19) -> 105150000 | P19: - | Q19: =SEPTEMBER!E25-R19-S19 -> 4050000 | S19: 60000000 | T19: =sum(Q19:S19) -> 64050000 | V19: 21400000 | X19: 16350000 | Y19: =sum(V19:X19) -> 37750000 | AA19: - | AB19: - | AC19: - | AD19: =sum(AA19:AC19) -> 0 | AF19: =+SEPTEMBER!H25-(AG19+AH19) -> 14100000 | AG19: 17910000 | AH19: 28500000 | AI19: =sum(AF19:AH19) -> 60510000 | AK19: =+SEPTEMBER!I25-(AL19+AM19) -> 16500000 | AN19: =sum(AK19:AM19) -> 16500000 | AR19: 5800000 | AS19: =sum(AP19:AR19) -> 5800000 | AU19: =SUM(B19,G19,L19,Q19,V19,AA19,AF19,AK19,AP19) -> 133940000 | AV19: =SUM(C19,H19,M19,R19,W19,AB19,AG19,AL19,AQ19) -> 17910000 | AW19: =SUM(D19,I19,N19,S19,X19,AC19,AH19,AM19,AR19) -> 181855000 | AX19: =E19+J19+O19+T19+Y19+AD19+AI19+AN19+AS19 -> 333705000
A20: 46283 | B20: 14210000 | D20: 32070000 | E20: =sum(B20:D20) -> 46280000 | J20: =sum(G20:I20) -> 0 | L20: 29500000 | M20: - | N20: 5565000 | O20: =sum(L20:N20) -> 35065000 | P20: - | Q20: =SEPTEMBER!E26-R20-S20 -> 38430000 | R20: 14500000 | S20: 36750000 | T20: =sum(Q20:S20) -> 89680000 | V20: =SEPTEMBER!F26-X20 -> 16250000 | X20: 20100000 | Y20: =sum(V20:X20) -> 36350000 | AA20: 2847500 | AB20: 3780000 | AD20: =sum(AA20:AC20) -> 6627500 | AF20: =+SEPTEMBER!H26-(AG20+AH20) -> 0 | AG20: 42100000 | AH20: 0 | AI20: =sum(AF20:AH20) -> 42100000 | AK20: =+SEPTEMBER!I26-(AL20+AM20) -> 27900000 | AM20: =8100000+5800000+14500000 -> 28400000 | AN20: =sum(AK20:AM20) -> 56300000 | AP20: 33750000 | AQ20: 0 | AR20: 16500000 | AS20: =sum(AP20:AR20) -> 50250000 | AU20: =SUM(B20,G20,L20,Q20,V20,AA20,AF20,AK20,AP20) -> 162887500 | AV20: =SUM(C20,H20,M20,R20,W20,AB20,AG20,AL20,AQ20) -> 60380000 | AW20: =SUM(D20,I20,N20,S20,X20,AC20,AH20,AM20,AR20) -> 139385000 | AX20: =E20+J20+O20+T20+Y20+AD20+AI20+AN20+AS20 -> 362652500
A21: 46284 | B21: 21100000 | D21: 42050000 | E21: =sum(B21:D21) -> 63150000 | J21: =sum(G21:I21) -> 0 | L21: 107240000 | M21: - | N21: 29690000 | O21: =sum(L21:N21) -> 136930000 | P21: - | Q21: =SEPTEMBER!E27-R21-S21 -> 20900000 | T21: =sum(Q21:S21) -> 20900000 | V21: 23440000 | X21: 169100000 | Y21: =sum(V21:X21) -> 192540000 | AA21: 2847500 | AB21: 2592500 | AD21: =sum(AA21:AC21) -> 5440000 | AF21: =+SEPTEMBER!H27-(AG21+AH21) -> 28080000 | AG21: 0 | AH21: 36500000 | AI21: =sum(AF21:AH21) -> 64580000 | AK21: =58765000-AM21 -> 48865000 | AM21: 9900000 | AN21: =sum(AK21:AM21) -> 58765000 | AP21: 23800000 | AS21: =sum(AP21:AR21) -> 23800000 | AU21: =SUM(B21,G21,L21,Q21,V21,AA21,AF21,AK21,AP21) -> 276272500 | AV21: =SUM(C21,H21,M21,R21,W21,AB21,AG21,AL21,AQ21) -> 2592500 | AW21: =SUM(D21,I21,N21,S21,X21,AC21,AH21,AM21,AR21) -> 287240000 | AX21: =E21+J21+O21+T21+Y21+AD21+AI21+AN21+AS21 -> 566105000
A22: 46285 | B22: 44845000 | D22: 20900000 | E22: =sum(B22:D22) -> 65745000 | J22: =sum(G22:I22) -> 0 | L22: 61700500 | M22: - | N22: 33207000 | O22: =sum(L22:N22) -> 94907500 | P22: - | Q22: =SEPTEMBER!E28-R22-S22 -> 51940000 | S22: 53150000 | T22: =sum(Q22:S22) -> 105090000 | V22: 57500000 | X22: 36800000 | Y22: =sum(V22:X22) -> 94300000 | AA22: 15406250 | AD22: =sum(AA22:AC22) -> 15406250 | AF22: =+SEPTEMBER!H28-(AG22+AH22) -> 17300000 | AG22: 16500000 | AH22: 29700000 | AI22: =sum(AF22:AH22) -> 63500000 | AK22: =46790000-AM22 -> 20680000 | AM22: =14500000+11610000 -> 26110000 | AN22: =sum(AK22:AM22) -> 46790000 | AP22: 40700000 | AS22: =sum(AP22:AR22) -> 40700000 | AU22: =SUM(B22,G22,L22,Q22,V22,AA22,AF22,AK22,AP22) -> 310071750 | AV22: =SUM(C22,H22,M22,R22,W22,AB22,AG22,AL22,AQ22) -> 16500000 | AW22: =SUM(D22,I22,N22,S22,X22,AC22,AH22,AM22,AR22) -> 199867000 | AX22: =E22+J22+O22+T22+Y22+AD22+AI22+AN22+AS22 -> 526438750
A23: 46286 | B23: =SEPTEMBER!B29-C23-D23 -> 32850000 | D23: 30420000 | E23: =sum(B23:D23) -> 63270000 | J23: =sum(G23:I23) -> 0 | L23: 17400000 | M23: - | N23: 91120000 | O23: =sum(L23:N23) -> 108520000 | P23: - | Q23: =SEPTEMBER!E29-R23-S23 -> 44750000 | S23: 11600000 | T23: =sum(Q23:S23) -> 56350000 | V23: =SEPTEMBER!F29-X23 -> 50710000 | X23: 26800000 | Y23: =sum(V23:X23) -> 77510000 | AA23: 3166250 | AD23: =sum(AA23:AC23) -> 3166250 | AF23: =+SEPTEMBER!H29-(AG23+AH23) -> 42810000 | AG23: 0 | AH23: =+10300000+14500000 -> 24800000 | AI23: =sum(AF23:AH23) -> 67610000 | AK23: 11360000 | AN23: =sum(AK23:AM23) -> 11360000 | AP23: 20850000 | AS23: =sum(AP23:AR23) -> 20850000 | AU23: =SUM(B23,G23,L23,Q23,V23,AA23,AF23,AK23,AP23) -> 223896250 | AV23: =SUM(C23,H23,M23,R23,W23,AB23,AG23,AL23,AQ23) -> 0 | AW23: =SUM(D23,I23,N23,S23,X23,AC23,AH23,AM23,AR23) -> 184740000 | AX23: =E23+J23+O23+T23+Y23+AD23+AI23+AN23+AS23 -> 408636250
